Internal Server Error: /
Traceback (most recent call last):
  File "/home/alex/Projects/DevOps-Py-Draft/venv/lib/python3.12/site-packages/django/db/backends/utils.py", line 105, in _execute
    return self.cursor.execute(sql, params)
           ^^^^^^^^^^^^^^^^^^^^^^^^^^^^^^^^
psycopg2.errors.UndefinedTable: relation "profiles_savedcompany" does not exist
LINE 1: ...mpany_id", "profiles_savedcompany"."user_id" FROM "profiles_...
                                                             ^


The above exception was the direct cause of the following exception:

Traceback (most recent call last):
  File "/home/alex/Projects/DevOps-Py-Draft/venv/lib/python3.12/site-packages/django/core/handlers/exception.py", line 55, in inner
    response = get_response(request)
               ^^^^^^^^^^^^^^^^^^^^^
  File "/home/alex/Projects/DevOps-Py-Draft/venv/lib/python3.12/site-packages/django/core/handlers/base.py", line 197, in _get_response
    response = wrapped_callback(request, *callback_args, **callback_kwargs)
               ^^^^^^^^^^^^^^^^^^^^^^^^^^^^^^^^^^^^^^^^^^^^^^^^^^^^^^^^^^^^
  File "/home/alex/Projects/DevOps-Py-Draft/venv/lib/python3.12/site-packages/django/views/generic/base.py", line 104, in view
    return self.dispatch(request, *args, **kwargs)
           ^^^^^^^^^^^^^^^^^^^^^^^^^^^^^^^^^^^^^^^
  File "/home/alex/Projects/DevOps-Py-Draft/venv/lib/python3.12/site-packages/django/views/generic/base.py", line 143, in dispatch
    return handler(request, *args, **kwargs)
           ^^^^^^^^^^^^^^^^^^^^^^^^^^^^^^^^^
  File "/home/alex/Projects/DevOps-Py-Draft/profiles/views.py", line 21, in get
    for saved_company in latest_saved_companies:
  File "/home/alex/Projects/DevOps-Py-Draft/venv/lib/python3.12/site-packages/django/db/models/query.py", line 400, in __iter__
    self._fetch_all()
  File "/home/alex/Projects/DevOps-Py-Draft/venv/lib/python3.12/site-packages/django/db/models/query.py", line 1928, in _fetch_all
    self._result_cache = list(self._iterable_class(self))
                         ^^^^^^^^^^^^^^^^^^^^^^^^^^^^^^^^
  File "/home/alex/Projects/DevOps-Py-Draft/venv/lib/python3.12/site-packages/django/db/models/query.py", line 91, in __iter__
    results = compiler.execute_sql(
              ^^^^^^^^^^^^^^^^^^^^^
  File "/home/alex/Projects/DevOps-Py-Draft/venv/lib/python3.12/site-packages/django/db/models/sql/compiler.py", line 1574, in execute_sql
    cursor.execute(sql, params)
  File "/home/alex/Projects/DevOps-Py-Draft/venv/lib/python3.12/site-packages/django/db/backends/utils.py", line 122, in execute
    return super().execute(sql, params)
           ^^^^^^^^^^^^^^^^^^^^^^^^^^^^
  File "/home/alex/Projects/DevOps-Py-Draft/venv/lib/python3.12/site-packages/django/db/backends/utils.py", line 79, in execute
    return self._execute_with_wrappers(
           ^^^^^^^^^^^^^^^^^^^^^^^^^^^^
  File "/home/alex/Projects/DevOps-Py-Draft/venv/lib/python3.12/site-packages/django/db/backends/utils.py", line 92, in _execute_with_wrappers
    return executor(sql, params, many, context)
           ^^^^^^^^^^^^^^^^^^^^^^^^^^^^^^^^^^^^
  File "/home/alex/Projects/DevOps-Py-Draft/venv/lib/python3.12/site-packages/django/db/backends/utils.py", line 100, in _execute
    with self.db.wrap_database_errors:
  File "/home/alex/Projects/DevOps-Py-Draft/venv/lib/python3.12/site-packages/django/db/utils.py", line 91, in __exit__
    raise dj_exc_value.with_traceback(traceback) from exc_value
  File "/home/alex/Projects/DevOps-Py-Draft/venv/lib/python3.12/site-packages/django/db/backends/utils.py", line 105, in _execute
    return self.cursor.execute(sql, params)
           ^^^^^^^^^^^^^^^^^^^^^^^^^^^^^^^^
django.db.utils.ProgrammingError: relation "profiles_savedcompany" does not exist
LINE 1: ...mpany_id", "profiles_savedcompany"."user_id" FROM "profiles_...
                                                             ^

"GET / HTTP/1.1" 500 142725
